<?xml version="1.0"?>
<robot xmlns:xacro="http://www.ros.org/wiki/xacro" >


    <material name="white">
        <color rgba="1 1 1 1" />
    </material>

    <material name="orange">
        <color rgba="1 0.3 0.1 1" />
    </material>

    <material name="blue">
        <color rgba="0.2 0.2 1 1" />
    </material>

    <material name="black">
        <color rgba="0 0 0 1" />
    </material>

    <link name="base_link"></link>

    <joint name="body_joint" type="fixed">
        <parent link="base_link"/>
        <child link="body"/>
        <origin xyz="-0.065 0 0"/>
    </joint>

    <link name="body">
        <visual>
            <origin xyz = "0.075 0 0.11"/>
            <geometry>
                <box size="0.15 0.15 0.22"/>
            </geometry>
            <material name="blue"/>
        </visual>
    </link>

    <joint name="left_wheel_joint" type="continuous">
        <parent link="base_link"/>
        <child link="left_wheel"/>
        <origin xyz="0 0.1 0" rpy="-1.57 0 0"/>
        <axis xyz="0 0 1"/>
    </joint>

    <link name="left_wheel">
        <visual>
            <geometry>
                <cylinder radius="0.034" length="0.025"/>
            </geometry>
            <material name="black"/>
        </visual>
    </link>

    <joint name="right_wheel_joint" type="continuous">
        <parent link="base_link"/>
        <child link="right_wheel"/>
        <origin xyz="0 -0.1 0" rpy="1.57 0 0"/>
        <axis xyz="0 0 -1"/>
    </joint>

    <link name="right_wheel">
        <visual>
            <geometry>
                <cylinder radius="0.034" length="0.025"/>
            </geometry>
            <material name="black"/>
        </visual>
    </link>

    <joint name="castor_joint" type="fixed">
        <parent link="body"/>
        <child link="castor_wheel"/>
        <origin xyz="0.14 0 0"/>
    </joint>

    <link name="castor_wheel">
        <visual>
            <geometry>
                <sphere radius = "0.034"/>
            </geometry>
            <material name="orange"/>
        </visual>
    </link>

</robot>
